Workbook

Sheet Budget Plan
B1: SweatShell — Kế hoạch ngân sách 5 năm
B2: Đơn vị: TRIỆU ĐỒNG (trừ các dòng ghi rõ đơn vị khác). Xanh dương = nhập tay · Xanh lá = lấy từ sheet BOM · Đen = công thức.
B4: Năm | C4: Y1 (Thử nghiệm) | D4: Y2 (Có khách) | E4: Y3 (Mở rộng) | F4: Y4 (Tăng trưởng) | G4: Y5 (Nhân vùng) | H4: Giả định
B5: DOANH THU | C5: =C8+C11 -> 84 | D5: =D8+D11 -> 780 | E5: =E8+E11 -> 3840 | F5: =F8+F11 -> 11400 | G5: =G8+G11 -> 26400 | H5: Doanh thu tấm + doanh thu bộ điều khiển
B6: Sản lượng tấm (m²) | C6: 1000 | D6: 10000 | E6: 50000 | F6: 150000 | G6: 350000 | H6: Y1 ≈ 25–30 mái thử nghiệm. Y5 ≈ 9.000 mái — vẫn rất nhỏ so với số hộ chăn nuôi/nhà màng ở VN.
B7: Giá bán tấm (₫/m²) | C7: 60000 | D7: 60000 | E7: 60000 | F7: 60000 | G7: 60000 | H7: Giá vốn ~28.000₫/m² → biên gộp ~53%. Mái 30 m² ≈ 1,8 triệu ₫.
B8: Doanh thu tấm | C8: =C6*C7/1000000 -> 60 | D8: =D6*D7/1000000 -> 600 | E8: =E6*E7/1000000 -> 3000 | F8: =F6*F7/1000000 -> 9000 | G8: =G6*G7/1000000 -> 21000
B9: Sản lượng bộ điều khiển (bộ) | C9: 20 | D9: 150 | E9: 700 | F9: 2000 | G9: 4500 | H9: ≈ 1 bộ cho mỗi 70–80 m² tấm. Đa số hộ mua tấm trước, bộ điều khiển sau.
B10: Giá bán bộ điều khiển (₫/bộ) | C10: 1200000 | D10: 1200000 | E10: 1200000 | F10: 1200000 | G10: 1200000 | H10: Bản FULL. Bản LITE bán ~800.000₫ — nên là lựa chọn mặc định khi chào hàng.
B11: Doanh thu bộ điều khiển | C11: =C9*C10/1000000 -> 24 | D11: =D9*D10/1000000 -> 180 | E11: =E9*E10/1000000 -> 840 | F11: =F9*F10/1000000 -> 2400 | G11: =G9*G10/1000000 -> 5400
B13: CAPEX
B14: Thiết bị sản xuất | C14: 85 | D14: 180 | E14: 400 | F14: 300 | G14: 500 | H14: Y1: máy nghiền, bàn phủ, giàn sấy, dụng cụ đo. Chi tiết ở sheet BOM mục C.
B15: Khuôn, đồ gá, dụng cụ | C15: 15 | D15: 0 | E15: 0 | F15: 0 | G15: 0
B16: Thiết bị kiểm nghiệm | C16: 20 | D16: 0 | E16: 0 | F16: 0 | G16: 0 | H16: Rẻ hơn nhiều nếu thuê lab trường ĐH thay vì mua.
B18: OPEX
B19: Giá vốn — vật liệu tấm | C19: =C6*BOM!$F$31/1000000 -> 27.9675 | D19: =D6*BOM!$F$31/1000000 -> 279.675 | E19: =E6*BOM!$F$31/1000000 -> 1398.375 | F19: =F6*BOM!$F$31/1000000 -> 4195.125 | G19: =G6*BOM!$F$31/1000000 -> 9788.625 | H19: Sản lượng m² × giá vốn/m² (sheet BOM, ô F31)
B20: Giá vốn — bộ điều khiển | C20: =C9*BOM!$F$20/1000000 -> 10.88 | D20: =D9*BOM!$F$20/1000000 -> 81.6 | E20: =E9*BOM!$F$20/1000000 -> 380.8 | F20: =F9*BOM!$F$20/1000000 -> 1088 | G20: =G9*BOM!$F$20/1000000 -> 2448 | H20: Số bộ × giá vốn bản FULL (sheet BOM, ô F20)
B21: Nhân sự | C21: 240 | D21: 480 | E21: 1080 | F21: 2160 | G21: 3600 | H21: Y1: 2 người toàn thời gian + sinh viên bán thời gian. Y5: ~15 người.
B22: Marketing & kênh phân phối | C22: 60 | D22: 180 | E22: 500 | F22: 1200 | G22: 2400 | H22: Hội nông dân, đại lý vật tư nông nghiệp, mái mẫu tại xã. Kênh này hiệu quả hơn quảng cáo online với nhóm khách này.
B23: R&D & thử nghiệm đồng ruộng | C23: 80 | D23: 150 | E23: 300 | F23: 500 | G23: 800 | H23: Đo thật trên mái thật qua mùa khô — không có số liệu này thì không bán được.
B24: Vận chuyển & lắp đặt | C24: =C5*$C$28 -> 4.2 | D24: =D5*$C$28 -> 39 | E24: =E5*$C$28 -> 192 | F24: =F5*$C$28 -> 570 | G24: =G5*$C$28 -> 1320 | H24: Doanh thu × tỷ lệ ở ô C28
B25: Xưởng, điện nước | C25: 36 | D25: 90 | E25: 240 | F25: 500 | G25: 900
B26: Hành chính, pháp lý, chứng nhận | C26: 50 | D26: 80 | E26: 150 | F26: 250 | G26: 400 | H26: Gồm kiểm nghiệm an toàn vật liệu — cần có trước khi bán đại trà.
B28: Tỷ lệ vận chuyển & lắp đặt (% doanh thu) | C28: 0.05 | H28: Nông thôn, đường xa, hàng cồng kềnh — đừng để dưới 4%.
B30: Tổng CAPEX | C30: =SUM(C14:C16) -> 120 | D30: =SUM(D14:D16) -> 180 | E30: =SUM(E14:E16) -> 400 | F30: =SUM(F14:F16) -> 300 | G30: =SUM(G14:G16) -> 500
B31: Tổng OPEX | C31: =SUM(C19:C26) -> 509.0475 | D31: =SUM(D19:D26) -> 1380.275 | E31: =SUM(E19:E26) -> 4241.175 | F31: =SUM(F19:F26) -> 10463.125 | G31: =SUM(G19:G26) -> 21656.625
B32: TỔNG CHI PHÍ | C32: =C30+C31 -> 629.0475 | D32: =D30+D31 -> 1560.275 | E32: =E30+E31 -> 4641.175 | F32: =F30+F31 -> 10763.125 | G32: =G30+G31 -> 22156.625
B34: LỢI NHUẬN RÒNG (FCF) | C34: =C5-C32 -> -545.0475 | D34: =D5-D32 -> -780.275 | E34: =E5-E32 -> -801.175 | F34: =F5-F32 -> 636.875 | G34: =G5-G32 -> 4243.375 | H34: Doanh thu − tổng chi phí
B36: LUỸ KẾ | C36: =C34 -> -545.0475 | D36: =C36+D34 -> -1325.3225 | E36: =D36+E34 -> -2126.4975 | F36: =E36+F34 -> -1489.6225 | G36: =F36+G34 -> 2753.7525 | H36: Số âm sâu nhất chính là số vốn cần huy động.
B38: CHỈ SỐ KIỂM TRA
B39: Biên lợi nhuận gộp | C39: =IFERROR((C5-C19-C20)/C5,0) -> 0.53752976 | D39: =IFERROR((D5-D19-D20)/D5,0) -> 0.53682692 | E39: =IFERROR((E5-E19-E20)/E5,0) -> 0.53667318 | F39: =IFERROR((F5-F19-F20)/F5,0) -> 0.53656798 | G39: =IFERROR((G5-G19-G20)/G5,0) -> 0.53649148 | H39: Dưới 45% là báo động — không đủ gánh chi phí cố định.
B40: Chi phí cố định / doanh thu | C40: =IFERROR(((C21+C22+C23+C25+C26))/C5,0) -> 5.547619 | D40: =IFERROR(((D21+D22+D23+D25+D26))/D5,0) -> 1.2564103 | E40: =IFERROR(((E21+E22+E23+E25+E26))/E5,0) -> 0.59114583 | F40: =IFERROR(((F21+F22+F23+F25+F26))/F5,0) -> 0.40438596 | G40: =IFERROR(((G21+G22+G23+G25+G26))/G5,0) -> 0.30681818 | H40: Phải tụt xuống dưới biên gộp thì mới có lãi.
B41: Giá bán 1 mái 30 m² (triệu ₫) | C41: =30*C7/1000000 -> 1.8 | D41: =30*D7/1000000 -> 1.8 | E41: =30*E7/1000000 -> 1.8 | F41: =30*F7/1000000 -> 1.8 | G41: =30*G7/1000000 -> 1.8 | H41: Con số nông dân thật sự nghe thấy. Trên 2 triệu là rất khó bán lần đầu.
B44: CÁCH DÙNG FILE NÀY
B45: • Chỉ sửa các ô CHỮ XANH DƯƠNG — sản lượng, giá bán, và các khoản chi theo năm. Mọi ô khác tự tính.
B46: • Giá vốn tấm và bộ điều khiển nằm ở sheet BOM. Sửa đơn giá linh kiện ở đó, bảng này tự cập nhật.
B47: • Dòng LUỸ KẾ cho biết cần bao nhiêu vốn: số âm sâu nhất là đỉnh thiếu hụt tiền mặt.
B48: • Toàn bộ giá linh kiện tra ngày 03/10/2026; ô nào là ƯỚC TÍNH đều ghi rõ ở cột ghi chú sheet BOM.

Sheet BOM
B1: SweatShell — Định mức thiết bị & giá vốn
B2: Giá tham khảo thị trường Việt Nam, tra ngày 03/10/2026. Ô chữ xanh dương = số nhập tay, sửa được.
B4: A. BỘ ĐIỀU KHIỂN (1 bộ cho 1 mái)
B5: Linh kiện | C5: SL | D5: Giá lẻ (₫) | E5: Giá sỉ ≥100 (₫) | F5: Thành tiền sỉ (₫) | G5: Ghi chú / nguồn
B6: ESP32 DevKit V1 (ESP-WROOM-32) | C6: 1 | D6: 140000 | E6: 85000 | F6: =C6*E6 -> 85000 | G6: Giá lẻ linhkienvietnam.vn. Sỉ: mua module trần ESP-WROOM-32 + tự làm PCB.
B7: Cảm biến nhiệt độ DS18B20 (chống nước) | C7: 3 | D7: 14000 | E7: 9000 | F7: =C7*E7 -> 27000 | G7: 14.000₫/cái lẻ — linhkienthanhcong.com. 3 cái: trong nhà, ngoài trời, mặt tấm.
B8: Cảm biến độ ẩm điện dung (gel) | C8: 1 | D8: 35000 | E8: 22000 | F8: =C8*E8 -> 22000 | G8: Ước tính. Phải dùng loại điện dung — loại điện trở ăn mòn trong vài tuần.
B9: Máy bơm chìm mini 12V, 150 L/h | C9: 1 | D9: 25000 | E9: 18000 | F9: =C9*E9 -> 18000 | G9: 25.000₫ lẻ — chotroihn.vn (MB365, cột áp 1,5 m). Đủ cho mái 1 tầng.
B10: Module relay 2 kênh | C10: 1 | D10: 25000 | E10: 15000 | F10: =C10*E10 -> 15000 | G10: Ước tính.
B11: Nguồn 12V 2A + bảo vệ | C11: 1 | D11: 70000 | E11: 45000 | F11: =C11*E11 -> 45000 | G11: Ước tính.
B12: Hộp chống nước IP65 + ốc siết cáp | C12: 1 | D12: 80000 | E12: 50000 | F12: =C12*E12 -> 50000 | G12: Ước tính. Bắt buộc — hộp đặt ngoài mái, mưa nắng quanh năm.
B13: Dây điện, ống dẫn nước, đầu nối | C13: 1 | D13: 60000 | E13: 40000 | F13: =C13*E13 -> 40000 | G13: Ước tính.
B14: PCB + lắp ráp + kiểm tra | C14: 1 | D14: 0 | E14: 60000 | F14: =C14*E14 -> 60000 | G14: Chỉ phát sinh khi sản xuất loạt; làm tay ở bản thử nên giá lẻ = 0.
B15: Cộng — bản LITE (không motor, cuốn tay) | D15: =SUMPRODUCT(C6:C14,D6:D14) -> 477000 | F15: =SUM(F6:F14) -> 362000 | G15: Đo nhiệt độ + tự tưới gel. Nông dân tự kéo màn bằng dây. Đây là bản nên bán cho đa số hộ.
B17: Thêm cho bản FULL (cuốn tự động)
B18: Động cơ giảm tốc 12V trục vít + driver | C18: 1 | D18: 250000 | E18: 170000 | F18: =C18*E18 -> 170000 | G18: Ước tính. KHÔNG dùng 28BYJ-48 (55.000₫, caka.vn) ngoài thực địa — mô-men ~0,3 kg·cm, chỉ đủ cho mô hình demo.
B19: Công tắc hành trình (giới hạn cuốn) | C19: 2 | D19: 10000 | E19: 6000 | F19: =C19*E19 -> 12000 | G19: Ước tính. Thiếu nó thì motor kéo quá hành trình và rách tấm.
B20: Cộng — bản FULL | D20: =D15+SUMPRODUCT(C18:C19,D18:D19) -> 747000 | F20: =F15+SUM(F18:F19) -> 544000 | G20: Giá vốn 1 bộ FULL ở sản lượng 100 bộ.
B22: B. TẤM SWEATSHELL — giá vốn cho 1 m²
B23: Vật liệu | C23: Định mức /m² | D23: Đơn vị | E23: Đơn giá (₫) | F23: Thành tiền (₫/m²) | G23: Ghi chú / nguồn
B24: Lưới che nắng VN (lớp nền) | C24: 1.05 | D24: m² | E24: 5500 | F24: =C24*E24 -> 5775 | G24: 4.500–6.500 ₫/m² — anhphatgroup.com. Lấy 5.500 và cộng 5% hao cắt.
B25: Bột vỏ trứng (phế phẩm + nghiền) | C25: 0.3 | D25: kg | E25: 2000 | F25: =C25*E25 -> 600 | G25: Vỏ trứng xin từ lò ấp/nhà hàng gần như miễn phí; 2.000₫/kg là chi phí rửa, sấy, nghiền.
B26: Sodium alginate | C26: 0.06 | D26: kg | E26: 230000 | F26: =C26*E26 -> 13800 | G26: ~9 USD/kg (imarcgroup.com Q2-2026, Nhật 11,47 / Tây Ban Nha 8,68). ĐÂY LÀ KHOẢN ĐẮT NHẤT — xem mục D.
B27: CaCl₂ (tạo liên kết gel) | C27: 0.03 | D27: kg | E27: 25000 | F27: =C27*E27 -> 750 | G27: Ước tính, hoá chất công nghiệp.
B28: Chất kết dính phủ (PVA/acrylic) | C28: 0.05 | D28: kg | E28: 40000 | F28: =C28*E28 -> 2000 | G28: Ước tính.
B29: Nhân công phủ + sấy | C29: 1 | D29: m² | E29: 2500 | F29: =C29*E29 -> 2500 | G29: Ước tính, ~250.000₫/ngày cho 100 m².
B30: Hao hụt sản xuất | C30: 0.1 | F30: =C30*SUM(F24:F29) -> 2542.5 | G30: Mẻ gel hỏng, cắt thừa, tấm không đạt.
B31: GIÁ VỐN 1 m² TẤM | F31: =SUM(F24:F30) -> 27967.5
B33: C. THIẾT BỊ SẢN XUẤT (CAPEX, triệu ₫)
B34: Thiết bị | C34: Năm | D34: Giá (triệu ₫) | G34: Ghi chú
B35: Máy nghiền vỏ trứng (búa, 50 kg/h) | C35: Y1 | D35: 25 | G35: Loại dùng cho thức ăn chăn nuôi, mua lại máy cũ được.
B36: Bàn phủ + con lăn + khung căng | C36: Y1 | D36: 30 | G36: Tự đóng, thợ cơ khí địa phương.
B37: Tủ sấy / giàn phơi có mái | C37: Y1 | D37: 20 | G37: Sấy bằng nắng là rẻ nhất, chỉ cần mái che mưa.
B38: Cân, dụng cụ đo, nhiệt kế hồng ngoại | C38: Y1 | D38: 10 | G38: Bắt buộc để kiểm tra định mức.
B39: Khuôn, đồ gá, bộ dụng cụ lắp | C39: Y1 | D39: 15
B40: Thiết bị kiểm nghiệm (độ bền, UV, bám dính) | C40: Y1 | D40: 20 | G40: Có thể thuê phòng lab trường ĐH thay vì mua.
B41: Máy phủ bán tự động | C41: Y2 | D41: 120 | G41: Khi vượt ~800 m²/tháng thì làm tay không kịp.
B42: Máy nghiền + sấy công suất lớn | C42: Y2 | D42: 60
B43: Dây chuyền phủ liên tục + kho | C43: Y3 | D43: 400
B44: Nâng cấp dây chuyền, xe giao hàng | C44: Y4 | D44: 300
...
